Workbook

Sheet Raw EOD Prices
A1: Batch ID | B1: Clearing Date | C1: Company | D1: ICE Name | E1: Instrument Name | F1: EOD Price | G1: Source URL | H1: Imported At
A2: ice-20260824-7bf9d81a3ef7 | B2: 46258 | C2: Oracle | D2: Oracle Cop | E2: ORCLE.SNRFOR.USD.XR14.100.2031-06-20 | F2: 95.0309 | G2: Open source | H2: 2026-08-25T08:30:08.959Z
A3: ice-20260824-7bf9d81a3ef7 | B3: 46258 | C3: CoreWeave | D3: COREWEAVE INC | E3: COREWEI.SNRFOR.USD.XR14.500.2031-06-20 | F3: 90.0135 | G3: Open source | H3: 2026-08-25T08:30:08.959Z
A4: ice-20260824-7bf9d81a3ef7 | B4: 46258 | C4: NVIDIA | D4: NVIDIA Corp | E4: NVIDIA.SNRFOR.USD.XR14.100.2031-06-20 | F4: 100.5487 | G4: Open source | H4: 2026-08-25T08:30:08.959Z
A5: ice-20260824-7bf9d81a3ef7 | B5: 46258 | C5: Amazon | D5: Amazon Com Inc | E5: AMZN.SNRFOR.USD.XR14.100.2031-06-20 | F5: 101.4668 | G5: Open source | H5: 2026-08-25T08:30:08.959Z
A6: ice-20260824-7bf9d81a3ef7 | B6: 46258 | C6: Google | D6: Alphabet Inc | E6: ALPHINC.SNRFOR.USD.XR14.100.2031-06-20 | F6: 101.7418 | G6: Open source | H6: 2026-08-25T08:30:08.959Z
A7: ice-20260824-7bf9d81a3ef7 | B7: 46258 | C7: Microsoft | D7: Microsoft Corp | E7: MSFT.SNRFOR.USD.XR14.100.2031-06-20 | F7: 102.2015 | G7: Open source | H7: 2026-08-25T08:30:08.959Z
A8: ice-20260824-7bf9d81a3ef7 | B8: 46258 | C8: Meta | D8: META PLATFORMS INC | E8: METAPL.SNRFOR.USD.XR14.100.2031-06-20 | F8: 100.1232 | G8: Open source | H8: 2026-08-25T08:30:08.959Z

Sheet Derived 5Y Spreads
A1: Batch ID | B1: Clearing Date | C1: Company | D1: Instrument Name | E1: EOD Price | F1: Coupon (bp) | G1: Spread (bp) | H1: Maturity Date | I1: Round-trip Price | J1: Price Residual | K1: Hazard Rate | L1: Curve ID | M1: Recovery Rate | N1: Model Version | O1: Quality Status | P1: Official Spread (bp) | Q1: Relative Error | R1: Source URL
A2: screenshot-reference-20260824-v1 | B2: 46183 | C2: Oracle | D2: SCREENSHOT.ORCLE.5Y | F2: 100 | G2: 160 | H2: 48019 | L2: screenshot-reference-not-applicable | M2: 0.4 | N2: screenshot-backfill-v1 | O2: stale
A3: screenshot-reference-20260824-v1 | B3: 46183 | C3: CoreWeave | D3: SCREENSHOT.COREWEI.5Y | F3: 500 | G3: 510 | H3: 48019 | L3: screenshot-reference-not-applicable | M3: 0.4 | N3: screenshot-backfill-v1 | O3: stale
A4: screenshot-reference-20260824-v1 | B4: 46183 | C4: Amazon | D4: SCREENSHOT.AMZN.5Y | F4: 100 | G4: 51 | H4: 48019 | L4: screenshot-reference-not-applicable | M4: 0.4 | N4: screenshot-backfill-v1 | O4: stale
A5: screenshot-reference-20260824-v1 | B5: 46183 | C5: Google | D5: SCREENSHOT.ALPHINC.5Y | F5: 100 | G5: 50 | H5: 48019 | L5: screenshot-reference-not-applicable | M5: 0.4 | N5: screenshot-backfill-v1 | O5: stale
A6: screenshot-reference-20260824-v1 | B6: 46183 | C6: Microsoft | D6: SCREENSHOT.MSFT.5Y | F6: 100 | G6: 39 | H6: 48019 | L6: screenshot-reference-not-applicable | M6: 0.4 | N6: screenshot-backfill-v1 | O6: stale
A7: screenshot-reference-20260824-v1 | B7: 46183 | C7: Meta | D7: SCREENSHOT.METAPL.5Y | F7: 100 | G7: 71 | H7: 48019 | L7: screenshot-reference-not-applicable | M7: 0.4 | N7: screenshot-backfill-v1 | O7: stale
A8: screenshot-reference-20260824-v1 | B8: 46184 | C8: Oracle | D8: SCREENSHOT.ORCLE.5Y | F8: 100 | G8: 158.8 | H8: 48019 | L8: screenshot-reference-not-applicable | M8: 0.4 | N8: screenshot-backfill-v1 | O8: stale
A9: screenshot-reference-20260824-v1 | B9: 46184 | C9: CoreWeave | D9: SCREENSHOT.COREWEI.5Y | F9: 500 | G9: 505.71 | H9: 48019 | L9: screenshot-reference-not-applicable | M9: 0.4 | N9: screenshot-backfill-v1 | O9: stale
A10: screenshot-reference-20260824-v1 | B10: 46184 | C10: Amazon | D10: SCREENSHOT.AMZN.5Y | F10: 100 | G10: 50.86 | H10: 48019 | L10: screenshot-reference-not-applicable | M10: 0.4 | N10: screenshot-backfill-v1 | O10: stale
A11: screenshot-reference-20260824-v1 | B11: 46184 | C11: Google | D11: SCREENSHOT.ALPHINC.5Y | F11: 100 | G11: 49.86 | H11: 48019 | L11: screenshot-reference-not-applicable | M11: 0.4 | N11: screenshot-backfill-v1 | O11: stale
A12: screenshot-reference-20260824-v1 | B12: 46184 | C12: Microsoft | D12: SCREENSHOT.MSFT.5Y | F12: 100 | G12: 38.86 | H12: 48019 | L12: screenshot-reference-not-applicable | M12: 0.4 | N12: screenshot-backfill-v1 | O12: stale
A13: screenshot-reference-20260824-v1 | B13: 46184 | C13: Meta | D13: SCREENSHOT.METAPL.5Y | F13: 100 | G13: 70.71 | H13: 48019 | L13: screenshot-reference-not-applicable | M13: 0.4 | N13: screenshot-backfill-v1 | O13: stale
... A364: screenshot-reference-20260824-v1 | B364: 46255 | C364: Meta | D364: SCREENSHOT.METAPL.5Y | F364: 100 | G364: 96 | H364: 48019 | L364: screenshot-reference-not-applicable | M364: 0.4 | N364: screenshot-backfill-v1 | O364: stale
A365: ice-20260824-7bf9d81a3ef7 | B365: 46258 | C365: Oracle | D365: ORCLE.SNRFOR.USD.XR14.100.2031-06-20 | E365: 95.0309 | F365: 100 | G365: 223.30089 | H365: 48019 | I365: 95.0309 | J365: 2.7000624e-13 | K365: 0.037529413 | L365: ust-par-zero-proxy-2026-08-24 | M365: 0.4 | N365: ice-isda-compatible-v1 | O365: model-derived | R365: Open source
A366: ice-20260824-7bf9d81a3ef7 | B366: 46258 | C366: CoreWeave | D366: COREWEI.SNRFOR.USD.XR14.500.2031-06-20 | E366: 90.0135 | F366: 500 | G366: 806.1393 | H366: 48019 | I366: 90.0135 | J366: 8.4980911e-12 | K366: 0.13551098 | L366: ust-par-zero-proxy-2026-08-24 | M366: 0.4 | N366: ice-isda-compatible-v1 | O366: model-derived | R366: Open source
A367: ice-20260824-7bf9d81a3ef7 | B367: 46258 | C367: NVIDIA | D367: NVIDIA.SNRFOR.USD.XR14.100.2031-06-20 | E367: 100.5487 | F367: 100 | G367: 87.075465 | H367: 48019 | I367: 100.5487 | J367: 3.2571279e-11 | K367: 0.014634029 | L367: ust-par-zero-proxy-2026-08-24 | M367: 0.4 | N367: ice-isda-compatible-v1 | O367: model-derived | R367: Open source
A368: ice-20260824-7bf9d81a3ef7 | B368: 46258 | C368: Amazon | D368: AMZN.SNRFOR.USD.XR14.100.2031-06-20 | E368: 101.4668 | F368: 100 | G368: 65.733555 | H368: 48019 | I368: 101.4668 | J368: 1.5404567e-11 | K368: 0.011047229 | L368: ust-par-zero-proxy-2026-08-24 | M368: 0.4 | N368: ice-isda-compatible-v1 | O368: model-derived | R368: Open source
A369: ice-20260824-7bf9d81a3ef7 | B369: 46258 | C369: Google | D369: ALPHINC.SNRFOR.USD.XR14.100.2031-06-20 | E369: 101.7418 | F369: 100 | G369: 59.408709 | H369: 48019 | I369: 101.7418 | J369: 1.2775558e-11 | K369: 0.0099842588 | L369: ust-par-zero-proxy-2026-08-24 | M369: 0.4 | N369: ice-isda-compatible-v1 | O369: model-derived | R369: Open source
A370: ice-20260824-7bf9d81a3ef7 | B370: 46258 | C370: Microsoft | D370: MSFT.SNRFOR.USD.XR14.100.2031-06-20 | E370: 102.2015 | F370: 100 | G370: 48.904252 | H370: 48019 | I370: 102.2015 | J370: 4.6810555e-11 | K370: 0.0082188575 | L370: ust-par-zero-proxy-2026-08-24 | M370: 0.4 | N370: ice-isda-compatible-v1 | O370: model-derived | R370: Open source
A371: ice-20260824-7bf9d81a3ef7 | B371: 46258 | C371: Meta | D371: METAPL.SNRFOR.USD.XR14.100.2031-06-20 | E371: 100.1232 | F371: 100 | G371: 97.086821 | H371: 48019 | I371: 100.1232 | J371: 1.4068746e-11 | K371: 0.016316586 | L371: ust-par-zero-proxy-2026-08-24 | M371: 0.4 | N371: ice-isda-compatible-v1 | O371: model-derived | R371: Open source

Sheet Daily Dashboard
A1: Date | B1: Company | C1: Spread (bp) | D1: 1D Δ (bp) | E1: 7D Δ (bp) | F1: 1M Δ (bp) | G1: EOD Price | H1: Quality Status | I1: Batch ID | J1: Instrument Name | K1: Source URL
A2: 46183 | B2: Oracle | C2: ='Derived 5Y Spreads'!G2 -> 160 | D2: =IFERROR(NA(),"") | E2: =IFERROR(NA(),"") | F2: =IFERROR(NA(),"") | G2: ='Derived 5Y Spreads'!E2 | H2: ='Derived 5Y Spreads'!O2 -> stale | I2: ='Derived 5Y Spreads'!A2 -> screenshot-reference-20260824-v1 | J2: ='Derived 5Y Spreads'!D2 -> SCREENSHOT.ORCLE.5Y
A3: 46183 | B3: CoreWeave | C3: ='Derived 5Y Spreads'!G3 -> 510 | D3: =IFERROR(NA(),"") | E3: =IFERROR(NA(),"") | F3: =IFERROR(NA(),"") | G3: ='Derived 5Y Spreads'!E3 | H3: ='Derived 5Y Spreads'!O3 -> stale | I3: ='Derived 5Y Spreads'!A3 -> screenshot-reference-20260824-v1 | J3: ='Derived 5Y Spreads'!D3 -> SCREENSHOT.COREWEI.5Y
A4: 46183 | B4: Amazon | C4: ='Derived 5Y Spreads'!G4 -> 51 | D4: =IFERROR(NA(),"") | E4: =IFERROR(NA(),"") | F4: =IFERROR(NA(),"") | G4: ='Derived 5Y Spreads'!E4 | H4: ='Derived 5Y Spreads'!O4 -> stale | I4: ='Derived 5Y Spreads'!A4 -> screenshot-reference-20260824-v1 | J4: ='Derived 5Y Spreads'!D4 -> SCREENSHOT.AMZN.5Y
A5: 46183 | B5: Google | C5: ='Derived 5Y Spreads'!G5 -> 50 | D5: =IFERROR(NA(),"") | E5: =IFERROR(NA(),"") | F5: =IFERROR(NA(),"") | G5: ='Derived 5Y Spreads'!E5 | H5: ='Derived 5Y Spreads'!O5 -> stale | I5: ='Derived 5Y Spreads'!A5 -> screenshot-reference-20260824-v1 | J5: ='Derived 5Y Spreads'!D5 -> SCREENSHOT.ALPHINC.5Y
A6: 46183 | B6: Microsoft | C6: ='Derived 5Y Spreads'!G6 -> 39 | D6: =IFERROR(NA(),"") | E6: =IFERROR(NA(),"") | F6: =IFERROR(NA(),"") | G6: ='Derived 5Y Spreads'!E6 | H6: ='Derived 5Y Spreads'!O6 -> stale | I6: ='Derived 5Y Spreads'!A6 -> screenshot-reference-20260824-v1 | J6: ='Derived 5Y Spreads'!D6 -> SCREENSHOT.MSFT.5Y
A7: 46183 | B7: Meta | C7: ='Derived 5Y Spreads'!G7 -> 71 | D7: =IFERROR(NA(),"") | E7: =IFERROR(NA(),"") | F7: =IFERROR(NA(),"") | G7: ='Derived 5Y Spreads'!E7 | H7: ='Derived 5Y Spreads'!O7 -> stale | I7: ='Derived 5Y Spreads'!A7 -> screenshot-reference-20260824-v1 | J7: ='Derived 5Y Spreads'!D7 -> SCREENSHOT.METAPL.5Y
A8: 46184 | B8: Oracle | C8: ='Derived 5Y Spreads'!G8 -> 158.8 | D8: =C8-'Derived 5Y Spreads'!G2 -> -1.2 | E8: =IFERROR(NA(),"") | F8: =IFERROR(NA(),"") | G8: ='Derived 5Y Spreads'!E8 | H8: ='Derived 5Y Spreads'!O8 -> stale | I8: ='Derived 5Y Spreads'!A8 -> screenshot-reference-20260824-v1 | J8: ='Derived 5Y Spreads'!D8 -> SCREENSHOT.ORCLE.5Y
A9: 46184 | B9: CoreWeave | C9: ='Derived 5Y Spreads'!G9 -> 505.71 | D9: =C9-'Derived 5Y Spreads'!G3 -> -4.29 | E9: =IFERROR(NA(),"") | F9: =IFERROR(NA(),"") | G9: ='Derived 5Y Spreads'!E9 | H9: ='Derived 5Y Spreads'!O9 -> stale | I9: ='Derived 5Y Spreads'!A9 -> screenshot-reference-20260824-v1 | J9: ='Derived 5Y Spreads'!D9 -> SCREENSHOT.COREWEI.5Y
A10: 46184 | B10: Amazon | C10: ='Derived 5Y Spreads'!G10 -> 50.86 | D10: =C10-'Derived 5Y Spreads'!G4 -> -0.14 | E10: =IFERROR(NA(),"") | F10: =IFERROR(NA(),"") | G10: ='Derived 5Y Spreads'!E10 | H10: ='Derived 5Y Spreads'!O10 -> stale | I10: ='Derived 5Y Spreads'!A10 -> screenshot-reference-20260824-v1 | J10: ='Derived 5Y Spreads'!D10 -> SCREENSHOT.AMZN.5Y
A11: 46184 | B11: Google | C11: ='Derived 5Y Spreads'!G11 -> 49.86 | D11: =C11-'Derived 5Y Spreads'!G5 -> -0.14 | E11: =IFERROR(NA(),"") | F11: =IFERROR(NA(),"") | G11: ='Derived 5Y Spreads'!E11 | H11: ='Derived 5Y Spreads'!O11 -> stale | I11: ='Derived 5Y Spreads'!A11 -> screenshot-reference-20260824-v1 | J11: ='Derived 5Y Spreads'!D11 -> SCREENSHOT.ALPHINC.5Y
A12: 46184 | B12: Microsoft | C12: ='Derived 5Y Spreads'!G12 -> 38.86 | D12: =C12-'Derived 5Y Spreads'!G6 -> -0.14 | E12: =IFERROR(NA(),"") | F12: =IFERROR(NA(),"") | G12: ='Derived 5Y Spreads'!E12 | H12: ='Derived 5Y Spreads'!O12 -> stale | I12: ='Derived 5Y Spreads'!A12 -> screenshot-reference-20260824-v1 | J12: ='Derived 5Y Spreads'!D12 -> SCREENSHOT.MSFT.5Y
A13: 46184 | B13: Meta | C13: ='Derived 5Y Spreads'!G13 -> 70.71 | D13: =C13-'Derived 5Y Spreads'!G7 -> -0.29 | E13: =IFERROR(NA(),"") | F13: =IFERROR(NA(),"") | G13: ='Derived 5Y Spreads'!E13 | H13: ='Derived 5Y Spreads'!O13 -> stale | I13: ='Derived 5Y Spreads'!A13 -> screenshot-reference-20260824-v1 | J13: ='Derived 5Y Spreads'!D13 -> SCREENSHOT.METAPL.5Y
A14: 46185 | B14: Oracle | C14: ='Derived 5Y Spreads'!G14 -> 157.6 | D14: =C14-'Derived 5Y Spreads'!G8 -> -1.2 | E14: =IFERROR(NA(),"") | F14: =IFERROR(NA(),"") | G14: ='Derived 5Y Spreads'!E14 | H14: ='Derived 5Y Spreads'!O14 -> stale | I14: ='Derived 5Y Spreads'!A14 -> screenshot-reference-20260824-v1 | J14: ='Derived 5Y Spreads'!D14 -> SCREENSHOT.ORCLE.5Y
A15: 46185 | B15: CoreWeave | C15: ='Derived 5Y Spreads'!G15 -> 501.43 | D15: =C15-'Derived 5Y Spreads'!G9 -> -4.28 | E15: =IFERROR(NA(),"") | F15: =IFERROR(NA(),"") | G15: ='Derived 5Y Spreads'!E15 | H15: ='Derived 5Y Spreads'!O15 -> stale | I15: ='Derived 5Y Spreads'!A15 -> screenshot-reference-20260824-v1 | J15: ='Derived 5Y Spreads'!D15 -> SCREENSHOT.COREWEI.5Y
A16: 46185 | B16: Amazon | C16: ='Derived 5Y Spreads'!G16 -> 50.71 | D16: =C16-'Derived 5Y Spreads'!G10 -> -0.15 | E16: =IFERROR(NA(),"") | F16: =IFERROR(NA(),"") | G16: ='Derived 5Y Spreads'!E16 | H16: ='Derived 5Y Spreads'!O16 -> stale | I16: ='Derived 5Y Spreads'!A16 -> screenshot-reference-20260824-v1 | J16: ='Derived 5Y Spreads'!D16 -> SCREENSHOT.AMZN.5Y
A17: 46185 | B17: Google | C17: ='Derived 5Y Spreads'!G17 -> 49.71 | D17: =C17-'Derived 5Y Spreads'!G11 -> -0.15 | E17: =IFERROR(NA(),"") | F17: =IFERROR(NA(),"") | G17: ='Derived 5Y Spreads'!E17 | H17: ='Derived 5Y Spreads'!O17 -> stale | I17: ='Derived 5Y Spreads'!A17 -> screenshot-reference-20260824-v1 | J17: ='Derived 5Y Spreads'!D17 -> SCREENSHOT.ALPHINC.5Y
A18: 46185 | B18: Microsoft | C18: ='Derived 5Y Spreads'!G18 -> 38.71 | D18: =C18-'Derived 5Y Spreads'!G12 -> -0.15 | E18: =IFERROR(NA(),"") | F18: =IFERROR(NA(),"") | G18: ='Derived 5Y Spreads'!E18 | H18: ='Derived 5Y Spreads'!O18 -> stale | I18: ='Derived 5Y Spreads'!A18 -> screenshot-reference-20260824-v1 | J18: ='Derived 5Y Spreads'!D18 -> SCREENSHOT.MSFT.5Y
A19: 46185 | B19: Meta | C19: ='Derived 5Y Spreads'!G19 -> 70.43 | D19: =C19-'Derived 5Y Spreads'!G13 -> -0.28 | E19: =IFERROR(NA(),"") | F19: =IFERROR(NA(),"") | G19: ='Derived 5Y Spreads'!E19 | H19: ='Derived 5Y Spreads'!O19 -> stale | I19: ='Derived 5Y Spreads'!A19 -> screenshot-reference-20260824-v1 | J19: ='Derived 5Y Spreads'!D19 -> SCREENSHOT.METAPL.5Y
... A31: 46189 | B31: Meta | C31: ='Derived 5Y Spreads'!G31 -> 69.29 | D31: =C31-'Derived 5Y Spreads'!G25 -> -0.28 | E31: =IFERROR(NA(),"") | F31: =IFERROR(NA(),"") | G31: ='Derived 5Y Spreads'!E31 | H31: ='Derived 5Y Spreads'!O31 -> stale | I31: ='Derived 5Y Spreads'!A31 -> screenshot-reference-20260824-v1 | J31: ='Derived 5Y Spreads'!D31 -> SCREENSHOT.METAPL.5Y
A32: 46190 | B32: Oracle | C32: ='Derived 5Y Spreads'!G32 -> 155.71 | D32: =C32-'Derived 5Y Spreads'!G26 -> 0.85 | E32: =C32-'Derived 5Y Spreads'!G2 -> -4.29 | F32: =IFERROR(NA(),"") | G32: ='Derived 5Y Spreads'!E32 | H32: ='Derived 5Y Spreads'!O32 -> stale | I32: ='Derived 5Y Spreads'!A32 -> screenshot-reference-20260824-v1 | J32: ='Derived 5Y Spreads'!D32 -> SCREENSHOT.ORCLE.5Y
A33: 46190 | B33: CoreWeave | C33: ='Derived 5Y Spreads'!G33 -> 480 | D33: =C33-'Derived 5Y Spreads'!G27 -> -4.29 | E33: =C33-'Derived 5Y Spreads'!G3 -> -30 | F33: =IFERROR(NA(),"") | G33: ='Derived 5Y Spreads'!E33 | H33: ='Derived 5Y Spreads'!O33 -> stale | I33: ='Derived 5Y Spreads'!A33 -> screenshot-reference-20260824-v1 | J33: ='Derived 5Y Spreads'!D33 -> SCREENSHOT.COREWEI.5Y
A34: 46190 | B34: Amazon | C34: ='Derived 5Y Spreads'!G34 -> 50 | D34: =C34-'Derived 5Y Spreads'!G28 -> -0.14 | E34: =C34-'Derived 5Y Spreads'!G4 -> -1 | F34: =IFERROR(NA(),"") | G34: ='Derived 5Y Spreads'!E34 | H34: ='Derived 5Y Spreads'!O34 -> stale | I34: ='Derived 5Y Spreads'!A34 -> screenshot-reference-20260824-v1 | J34: ='Derived 5Y Spreads'!D34 -> SCREENSHOT.AMZN.5Y
A35: 46190 | B35: Google | C35: ='Derived 5Y Spreads'!G35 -> 49 | D35: =C35-'Derived 5Y Spreads'!G29 -> -0.14 | E35: =C35-'Derived 5Y Spreads'!G5 -> -1 | F35: =IFERROR(NA(),"") | G35: ='Derived 5Y Spreads'!E35 | H35: ='Derived 5Y Spreads'!O35 -> stale | I35: ='Derived 5Y Spreads'!A35 -> screenshot-reference-20260824-v1 | J35: ='Derived 5Y Spreads'!D35 -> SCREENSHOT.ALPHINC.5Y
A36: 46190 | B36: Microsoft | C36: ='Derived 5Y Spreads'!G36 -> 38 | D36: =C36-'Derived 5Y Spreads'!G30 -> -0.14 | E36: =C36-'Derived 5Y Spreads'!G6 -> -1 | F36: =IFERROR(NA(),"") | G36: ='Derived 5Y Spreads'!E36 | H36: ='Derived 5Y Spreads'!O36 -> stale | I36: ='Derived 5Y Spreads'!A36 -> screenshot-reference-20260824-v1 | J36: ='Derived 5Y Spreads'!D36 -> SCREENSHOT.MSFT.5Y
A37: 46190 | B37: Meta | C37: ='Derived 5Y Spreads'!G37 -> 69 | D37: =C37-'Derived 5Y Spreads'!G31 -> -0.29 | E37: =C37-'Derived 5Y Spreads'!G7 -> -2 | F37: =IFERROR(NA(),"") | G37: ='Derived 5Y Spreads'!E37 | H37: ='Derived 5Y Spreads'!O37 -> stale | I37: ='Derived 5Y Spreads'!A37 -> screenshot-reference-20260824-v1 | J37: ='Derived 5Y Spreads'!D37 -> SCREENSHOT.METAPL.5Y
A38: 46191 | B38: Oracle | C38: ='Derived 5Y Spreads'!G38 -> 156.57 | D38: =C38-'Derived 5Y Spreads'!G32 -> 0.86 | E38: =C38-'Derived 5Y Spreads'!G8 -> -2.23 | F38: =IFERROR(NA(),"") | G38: ='Derived 5Y Spreads'!E38 | H38: ='Derived 5Y Spreads'!O38 -> stale | I38: ='Derived 5Y Spreads'!A38 -> screenshot-reference-20260824-v1 | J38: ='Derived 5Y Spreads'!D38 -> SCREENSHOT.ORCLE.5Y
A39: 46191 | B39: CoreWeave | C39: ='Derived 5Y Spreads'!G39 -> 490.71 | D39: =C39-'Derived 5Y Spreads'!G33 -> 10.71 | E39: =C39-'Derived 5Y Spreads'!G9 -> -15 | F39: =IFERROR(NA(),"") | G39: ='Derived 5Y Spreads'!E39 | H39: ='Derived 5Y Spreads'!O39 -> stale | I39: ='Derived 5Y Spreads'!A39 -> screenshot-reference-20260824-v1 | J39: ='Derived 5Y Spreads'!D39 -> SCREENSHOT.COREWEI.5Y
A40: 46191 | B40: Amazon | C40: ='Derived 5Y Spreads'!G40 -> 50.57 | D40: =C40-'Derived 5Y Spreads'!G34 -> 0.57 | E40: =C40-'Derived 5Y Spreads'!G10 -> -0.29 | F40: =IFERROR(NA(),"") | G40: ='Derived 5Y Spreads'!E40 | H40: ='Derived 5Y Spreads'!O40 -> stale | I40: ='Derived 5Y Spreads'!A40 -> screenshot-reference-20260824-v1 | J40: ='Derived 5Y Spreads'!D40 -> SCREENSHOT.AMZN.5Y
A41: 46191 | B41: Google | C41: ='Derived 5Y Spreads'!G41 -> 49.43 | D41: =C41-'Derived 5Y Spreads'!G35 -> 0.43 | E41: =C41-'Derived 5Y Spreads'!G11 -> -0.43 | F41: =IFERROR(NA(),"") | G41: ='Derived 5Y Spreads'!E41 | H41: ='Derived 5Y Spreads'!O41 -> stale | I41: ='Derived 5Y Spreads'!A41 -> screenshot-reference-20260824-v1 | J41: ='Derived 5Y Spreads'!D41 -> SCREENSHOT.ALPHINC.5Y
A42: 46191 | B42: Microsoft | C42: ='Derived 5Y Spreads'!G42 -> 38.29 | D42: =C42-'Derived 5Y Spreads'!G36 -> 0.29 | E42: =C42-'Derived 5Y Spreads'!G12 -> -0.57 | F42: =IFERROR(NA(),"") | G42: ='Derived 5Y Spreads'!E42 | H42: ='Derived 5Y Spreads'!O42 -> stale | I42: ='Derived 5Y Spreads'!A42 -> screenshot-reference-20260824-v1 | J42: ='Derived 5Y Spreads'!D42 -> SCREENSHOT.MSFT.5Y
A43: 46191 | B43: Meta | C43: ='Derived 5Y Spreads'!G43 -> 69.29 | D43: =C43-'Derived 5Y Spreads'!G37 -> 0.29 | E43: =C43-'Derived 5Y Spreads'!G13 -> -1.42 | F43: =IFERROR(NA(),"") | G43: ='Derived 5Y Spreads'!E43 | H43: ='Derived 5Y Spreads'!O43 -> stale | I43: ='Derived 5Y Spreads'!A43 -> screenshot-reference-20260824-v1 | J43: ='Derived 5Y Spreads'!D43 -> SCREENSHOT.METAPL.5Y
... A51: 46195 | B51: CoreWeave | C51: ='Derived 5Y Spreads'!G51 -> 533.57 | D51: =C51-'Derived 5Y Spreads'!G45 -> 32.14 | E51: =C51-'Derived 5Y Spreads'!G21 -> 45 | F51: =IFERROR(NA(),"") | G51: ='Derived 5Y Spreads'!E51 | H51: ='Derived 5Y Spreads'!O51 -> stale | I51: ='Derived 5Y Spreads'!A51 -> screenshot-reference-20260824-v1 | J51: ='Derived 5Y Spreads'!D51 -> SCREENSHOT.COREWEI.5Y
A52: 46195 | B52: NVIDIA | C52: ='Derived 5Y Spreads'!G52 -> 40 | D52: =IFERROR(NA(),"") | E52: =IFERROR(NA(),"") | F52: =IFERROR(NA(),"") | G52: ='Derived 5Y Spreads'!E52 | H52: ='Derived 5Y Spreads'!O52 -> stale | I52: ='Derived 5Y Spreads'!A52 -> screenshot-reference-20260824-v1 | J52: ='Derived 5Y Spreads'!D52 -> SCREENSHOT.NVIDIA.5Y
A53: 46195 | B53: Amazon | C53: ='Derived 5Y Spreads'!G53 -> 52.86 | D53: =C53-'Derived 5Y Spreads'!G46 -> 1.72 | E53: =C53-'Derived 5Y Spreads'!G22 -> 2.57 | F53: =IFERROR(NA(),"") | G53: ='Derived 5Y Spreads'!E53 | H53: ='Derived 5Y Spreads'!O53 -> stale | I53: ='Derived 5Y Spreads'!A53 -> screenshot-reference-20260824-v1 | J53: ='Derived 5Y Spreads'!D53 -> SCREENSHOT.AMZN.5Y
A54: 46195 | B54: Google | C54: ='Derived 5Y Spreads'!G54 -> 51.14 | D54: =C54-'Derived 5Y Spreads'!G47 -> 1.28 | E54: =C54-'Derived 5Y Spreads'!G23 -> 1.85 | F54: =IFERROR(NA(),"") | G54: ='Derived 5Y Spreads'!E54 | H54: ='Derived 5Y Spreads'!O54 -> stale | I54: ='Derived 5Y Spreads'!A54 -> screenshot-reference-20260824-v1 | J54: ='Derived 5Y Spreads'!D54 -> SCREENSHOT.ALPHINC.5Y
A55: 46195 | B55: Microsoft | C55: ='Derived 5Y Spreads'!G55 -> 39.43 | D55: =C55-'Derived 5Y Spreads'!G48 -> 0.86 | E55: =C55-'Derived 5Y Spreads'!G24 -> 1.14 | F55: =IFERROR(NA(),"") | G55: ='Derived 5Y Spreads'!E55 | H55: ='Derived 5Y Spreads'!O55 -> stale | I55: ='Derived 5Y Spreads'!A55 -> screenshot-reference-20260824-v1 | J55: ='Derived 5Y Spreads'!D55 -> SCREENSHOT.MSFT.5Y
A56: 46195 | B56: Meta | C56: ='Derived 5Y Spreads'!G56 -> 70.43 | D56: =C56-'Derived 5Y Spreads'!G49 -> 0.86 | E56: =C56-'Derived 5Y Spreads'!G25 -> 0.86 | F56: =IFERROR(NA(),"") | G56: ='Derived 5Y Spreads'!E56 | H56: ='Derived 5Y Spreads'!O56 -> stale | I56: ='Derived 5Y Spreads'!A56 -> screenshot-reference-20260824-v1 | J56: ='Derived 5Y Spreads'!D56 -> SCREENSHOT.METAPL.5Y
A57: 46196 | B57: Oracle | C57: ='Derived 5Y Spreads'!G57 -> 161.57 | D57: =C57-'Derived 5Y Spreads'!G50 -> 1.57 | E57: =C57-'Derived 5Y Spreads'!G26 -> 6.71 | F57: =IFERROR(NA(),"") | G57: ='Derived 5Y Spreads'!E57 | H57: ='Derived 5Y Spreads'!O57 -> stale | I57: ='Derived 5Y Spreads'!A57 -> screenshot-reference-20260824-v1 | J57: ='Derived 5Y Spreads'!D57 -> SCREENSHOT.ORCLE.5Y
A58: 46196 | B58: CoreWeave | C58: ='Derived 5Y Spreads'!G58 -> 544.29 | D58: =C58-'Derived 5Y Spreads'!G51 -> 10.72 | E58: =C58-'Derived 5Y Spreads'!G27 -> 60 | F58: =IFERROR(NA(),"") | G58: ='Derived 5Y Spreads'!E58 | H58: ='Derived 5Y Spreads'!O58 -> stale | I58: ='Derived 5Y Spreads'!A58 -> screenshot-reference-20260824-v1 | J58: ='Derived 5Y Spreads'!D58 -> SCREENSHOT.COREWEI.5Y
...

Sheet Discount Curves
A1: Curve ID | B1: As Of | C1: Currency | D1: Years | E1: Continuous Zero Rate | F1: Source Label | G1: Source URL
A2: ust-par-zero-proxy-2026-08-24 | B2: 46258 | C2: USD | D2: 0.083333333 | E2: 0.0379 | F2: U.S. Treasury par yields · continuous-zero proxy | G2: Open source
A3: ust-par-zero-proxy-2026-08-24 | B3: 46258 | C3: USD | D3: 0.125 | E3: 0.0378 | F3: U.S. Treasury par yields · continuous-zero proxy | G3: Open source
A4: ust-par-zero-proxy-2026-08-24 | B4: 46258 | C4: USD | D4: 0.16666667 | E4: 0.038 | F4: U.S. Treasury par yields · continuous-zero proxy | G4: Open source
A5: ust-par-zero-proxy-2026-08-24 | B5: 46258 | C5: USD | D5: 0.25 | E5: 0.0387 | F5: U.S. Treasury par yields · continuous-zero proxy | G5: Open source
A6: ust-par-zero-proxy-2026-08-24 | B6: 46258 | C6: USD | D6: 0.33333333 | E6: 0.039 | F6: U.S. Treasury par yields · continuous-zero proxy | G6: Open source
A7: ust-par-zero-proxy-2026-08-24 | B7: 46258 | C7: USD | D7: 0.5 | E7: 0.0396 | F7: U.S. Treasury par yields · continuous-zero proxy | G7: Open source
A8: ust-par-zero-proxy-2026-08-24 | B8: 46258 | C8: USD | D8: 1 | E8: 0.0404 | F8: U.S. Treasury par yields · continuous-zero proxy | G8: Open source
A9: ust-par-zero-proxy-2026-08-24 | B9: 46258 | C9: USD | D9: 2 | E9: 0.0424 | F9: U.S. Treasury par yields · continuous-zero proxy | G9: Open source
A10: ust-par-zero-proxy-2026-08-24 | B10: 46258 | C10: USD | D10: 3 | E10: 0.0431 | F10: U.S. Treasury par yields · continuous-zero proxy | G10: Open source
A11: ust-par-zero-proxy-2026-08-24 | B11: 46258 | C11: USD | D11: 5 | E11: 0.0441 | F11: U.S. Treasury par yields · continuous-zero proxy | G11: Open source
A12: ust-par-zero-proxy-2026-08-24 | B12: 46258 | C12: USD | D12: 7 | E12: 0.0455 | F12: U.S. Treasury par yields · continuous-zero proxy | G12: Open source
A13: ust-par-zero-proxy-2026-08-24 | B13: 46258 | C13: USD | D13: 10 | E13: 0.047 | F13: U.S. Treasury par yields · continuous-zero proxy | G13: Open source
... A15: ust-par-zero-proxy-2026-08-24 | B15: 46258 | C15: USD | D15: 30 | E15: 0.0523 | F15: U.S. Treasury par yields · continuous-zero proxy | G15: Open source

Sheet Contract Registry
A1: Company | B1: Aliases | C1: Symbols | D1: Currency | E1: Tier | F1: Restructuring | G1: Coupon (bp)
A2: Oracle | B2: ORACLE COP; ORACLE CORP; ORACLE CORPORATION | C2: ORCLE; ORCL | D2: USD | E2: SNRFOR | F2: XR14 | G2: 100
A3: CoreWeave | B3: COREWEAVE; COREWEAVE INC; COREWEAVE, INC. | C3: COREWEI; CRWV | D3: USD | E3: SNRFOR | F3: XR14 | G3: 500
A4: NVIDIA | B4: NVIDIA CORP; NVIDIA CORPORATION | C4: NVIDIA; NVDA | D4: USD | E4: SNRFOR | F4: XR14 | G4: 100
A5: Amazon | B5: AMAZON COM INC; AMAZON.COM INC; AMAZON INC | C5: AMZN | D5: USD | E5: SNRFOR | F5: XR14 | G5: 100
A6: Google | B6: ALPHABET INC; ALPHABET, INC.; GOOGLE INC; GOOGLE LLC | C6: ALPHINC; GOOG; GOOGL | D6: USD | E6: SNRFOR | F6: XR14 | G6: 100
A7: Microsoft | B7: MICROSOFT CORP; MICROSOFT CORPORATION | C7: MSFT | D7: USD | E7: SNRFOR | F7: XR14 | G7: 100
A8: Meta | B8: META PLATFORMS INC; META PLATFORMS, INC.; META PLATFORMS | C8: METAPL; META | D8: USD | E8: SNRFOR | F8: XR14 | G8: 100

Sheet Validation Log
A1: Batch ID | B1: Created At | C1: Level | D1: Code | E1: Company | F1: Message
A2: ice-empty-v1 | B2: 2026-08-25T07:49:40.977Z | C2: info | D2: initialized-empty | F2: Initialized without screenshot or DTCC values; waiting for the first ICE EOD Price import.
A3: ice-20260824-7bf9d81a3ef7 | B3: 2026-08-25T08:23:39.776Z | C3: warning | D3: model-derived | E3: Oracle | F3: No official spread benchmark supplied; model-derived only
A4: ice-20260824-7bf9d81a3ef7 | B4: 2026-08-25T08:23:39.776Z | C4: warning | D4: model-derived | E4: CoreWeave | F4: No official spread benchmark supplied; model-derived only
A5: ice-20260824-7bf9d81a3ef7 | B5: 2026-08-25T08:23:39.776Z | C5: warning | D5: model-derived | E5: NVIDIA | F5: No official spread benchmark supplied; model-derived only
A6: ice-20260824-7bf9d81a3ef7 | B6: 2026-08-25T08:23:39.776Z | C6: warning | D6: model-derived | E6: Amazon | F6: No official spread benchmark supplied; model-derived only
A7: ice-20260824-7bf9d81a3ef7 | B7: 2026-08-25T08:23:39.776Z | C7: warning | D7: model-derived | E7: Google | F7: No official spread benchmark supplied; model-derived only
A8: ice-20260824-7bf9d81a3ef7 | B8: 2026-08-25T08:23:39.776Z | C8: warning | D8: model-derived | E8: Microsoft | F8: No official spread benchmark supplied; model-derived only
A9: ice-20260824-7bf9d81a3ef7 | B9: 2026-08-25T08:23:39.776Z | C9: warning | D9: model-derived | E9: Meta | F9: No official spread benchmark supplied; model-derived only
A10: screenshot-reference-20260824-v1 | B10: 2026-08-25T08:30:05.427Z | C10: warning | D10: screenshot-history-backfill | F10: 2026-06-10 through 2026-08-21 history was digitized from the supplied chart image; values are visual references, not official ICE observations.

Sheet Methodology
A1: Key | B1: Value
A2: schemaVersion | B2: 1
A3: batchId | B3: ice-20260824-7bf9d81a3ef7
A4: generatedAt | B4: 2026-08-25T08:30:08.959Z
A5: modelVersion | B5: ice-isda-compatible-v1
A6: priceTolerance | B6: 0.005
A7: relativeBenchmarkTolerance | B7: 0.01
A8: note | B8: Model-derived unless an official spread benchmark passes validation.
A9: sourceDefinition | B9: ICE EOD Price is the source input; Spread (bp) is a model-derived estimate.
A10: officialStatus | B10: This workbook does not present model-derived spreads as official ICE spread quotations.
